Workbook
Name CriteriosConsultaProduto: 'Quadro de Resumo'!$AM$7:$AM$8
Name Lista_Produtos: TB_Produtos[[#All],[Produto]]
Name Lista_Produtos: TB_Produtos[[#All],[Produto]]
Name NativeTimeline_Data: #N/A
Name SegmentaçãodeDados_Data__Mês: #N/A
Name SegmentaçãodeDados_Empresa: #N/A
Name SegmentaçãodeDados_Fornecedor: #N/A
Name SegmentaçãodeDados_Produto: #N/A
Name SegmentaçãodeDados_Produto1: #N/A

Sheet Dashboard
B3: DASHBOARD
AE6: FATURAMENTO | AV6: DESPESAS | BM6: MARGEM DE LUCRO | CD6: MÉDIA DE VENDAS
AE8: =GETPIVOTDATA("[Measures].[Total Preco Venda]",Saídas!$H$5) -> 19042.5 | AV8: =GETPIVOTDATA("[Measures].[Despesas]",Entradas!$H$5) -> 5530 | BM8: =(AE8-AV8)/AV8 -> 2.4434901 | CD8: =GETPIVOTDATA("[Measures].[Media Venda]",Saídas!$H$5) -> 45.526316
Y13: FATURAMENTO X DESPESA | CD13: TOP 5 PRODUTOS MAIS VENDIDOS
Y34: ENTRADA X SAÍDA MENSAL | BK34: ENTRADA X SAÍDA | CD34: RANKING FATURAMENTO
Y36: Café

Sheet Tab Din Dashboard
K1: Voltar ao Dash
A3: ENTRADA X SAÍDA MENSAL | B3: Qtd Comprada | C3: Qtd Vendida | D3: Status | F3: Valores | I3: TOP 5 PRODUTOS MAIS VENDIDOS | J3: Qtd Vendida | K3: Qtd Comprada | O3: RANKING FATURAMENTO | P3: Soma de Preço de Venda | Q3: Status
A4: abr | B4: 350 | C4: 215 | D4: 1 | F4: Total Comprado | G4: 4365 | I4: Café | J4: 945 | K4: 1635 | O4: Café | P4: 5670 | Q4: 1
A5: ago | B5: 345 | C5: 263 | D5: 1 | F5: Total Vendido | G5: 2595 | I5: Chocolate Quente | J5: 500 | K5: 750 | O5: Chocolate Quente | P5: 4250 | Q5: 1
A6: dez | B6: 240 | C6: 168 | D6: 1 | I6: Pão de Queijo | J6: 400 | K6: 620 | O6: Pão de Queijo | P6: 3000 | Q6: 0
A7: fev | B7: 440 | C7: 235 | D7: 1 | I7: Coxinha | J7: 245 | K7: 550 | O7: Refrigerante | P7: 1680 | Q7: -1
A8: jan | B8: 390 | C8: 210 | D8: 1 | I8: Refrigerante | J8: 210 | K8: 350 | O8: Coxinha | P8: 1592.5 | Q8: -1
A9: jul | B9: 350 | C9: 295 | D9: 1 | I9: Total Geral | J9: 2300 | K9: 3905 | O9: Total Geral | P9: 16192.5 | Q9: 1
A10: jun | B10: 410 | C10: 170 | D10: 0
A11: mai | B11: 285 | C11: 177 | D11: 1
A12: mar | B12: 640 | C12: 315 | D12: 0
A13: nov | B13: 280 | C13: 119 | D13: 0
A14: out | B14: 236 | C14: 163 | D14: 1
A15: set | B15: 399 | C15: 265 | D15: 1
A16: Total Geral | B16: 4365 | C16: 2595 | D16: 1

Sheet Base Cálculos
A1: {=TB_Produtos[Produto]} -> Café | B1: =SUMIF(#REF!,A1,TB_Saídas[Quantidade Vendida]) -> #REF! | C1: =SUMIF(#REF!,A1,#REF!) -> #REF! | E1: Top 5 Mais Vendidos | J1: Faturamento x Despesas | P1: Entradas e Saídas (QTD) | T1: Entradas e Saídas (Anual)
A2: Pão | B2: =SUMIF(#REF!,A2,TB_Saídas[Quantidade Vendida]) -> #REF! | C2: =SUMIF(#REF!,A2,#REF!) -> #REF! | F2: Produto | G2: Qtd. Entradas | H2: Qtd. Saídas | J2: N Mês | K2: Mês | L2: Faturamento | M2: Despesas | O2: Produto | P2: Mês | Q2: Entradas | R2: Saídas | U2: Entradas | V2: Saídas
A3: Coxinha | B3: =SUMIF(#REF!,A3,TB_Saídas[Quantidade Vendida]) -> #REF! | C3: =SUMIF(#REF!,A3,#REF!) -> #REF! | E3: 1º | F3: =_xlfn.XLOOKUP(G3,B:B,A:A,"",0) -> #REF! | G3: =LARGE(B:B,1) -> #REF! | H3: =SUMIF(TB_Entradas[Código Produto],F3,TB_Entradas[Quantidade Comprada]) -> 0 | J3: 1 | K3: jan | L3: =SUMIF(TB_Saídas[Mês],'Base Cálculos'!J3,#REF!) -> #REF! | M3: =SUMIF(TB_Entradas[Mês],'Base Cálculos'!J3,#REF!) -> #REF! | O3: =Dashboard!Y36 -> Café | P3: =K3 -> jan | Q3: =SUMIFS(TB_Entradas[Quantidade Comprada],TB_Entradas[Código Produto],$O$3,TB_Entradas[Mês],J3) -> 0 | R3: =SUMIFS(TB_Saídas[Quantidade Vendida],#REF!,$O$3,TB_Saídas[Mês],'Base Cálculos'!J3) -> #REF! | T3: Total | U3: =SUM(Q3:Q14) -> 0 | V3: =SUM(R3:R14) -> #REF!
A4: Esfiha | B4: =SUMIF(#REF!,A4,TB_Saídas[Quantidade Vendida]) -> #REF! | C4: =SUMIF(#REF!,A4,#REF!) -> #REF! | E4: 2º | F4: =_xlfn.XLOOKUP(G4,B:B,A:A,"",0) -> #REF! | G4: =LARGE(B:B,2) -> #REF! | H4: =SUMIF(TB_Entradas[Código Produto],F4,TB_Entradas[Quantidade Comprada]) -> 0 | J4: 2 | K4: fev | L4: =SUMIF(TB_Saídas[Mês],'Base Cálculos'!J4,#REF!) -> #REF! | M4: =SUMIF(TB_Entradas[Mês],'Base Cálculos'!J4,#REF!) -> #REF! | P4: =K4 -> fev | Q4: =SUMIFS(TB_Entradas[Quantidade Comprada],TB_Entradas[Código Produto],$O$3,TB_Entradas[Mês],J4) -> 0 | R4: =SUMIFS(TB_Saídas[Quantidade Vendida],#REF!,$O$3,TB_Saídas[Mês],'Base Cálculos'!J4) -> #REF!
A5: Risoles | B5: =SUMIF(#REF!,A5,TB_Saídas[Quantidade Vendida]) -> #REF! | C5: =SUMIF(#REF!,A5,#REF!) -> #REF! | E5: 3º | F5: =_xlfn.XLOOKUP(G5,B:B,A:A,"",0) -> #REF! | G5: =LARGE(B:B,3) -> #REF! | H5: =SUMIF(TB_Entradas[Código Produto],F5,TB_Entradas[Quantidade Comprada]) -> 0 | J5: 3 | K5: mar | L5: =SUMIF(TB_Saídas[Mês],'Base Cálculos'!J5,#REF!) -> #REF! | M5: =SUMIF(TB_Entradas[Mês],'Base Cálculos'!J5,#REF!) -> #REF! | P5: =K5 -> mar | Q5: =SUMIFS(TB_Entradas[Quantidade Comprada],TB_Entradas[Código Produto],$O$3,TB_Entradas[Mês],J5) -> 0 | R5: =SUMIFS(TB_Saídas[Quantidade Vendida],#REF!,$O$3,TB_Saídas[Mês],'Base Cálculos'!J5) -> #REF!
A6: Empada | B6: =SUMIF(#REF!,A6,TB_Saídas[Quantidade Vendida]) -> #REF! | C6: =SUMIF(#REF!,A6,#REF!) -> #REF! | E6: 4º | F6: =_xlfn.XLOOKUP(G6,B:B,A:A,"",0) -> #REF! | G6: =LARGE(B:B,4) -> #REF! | H6: =SUMIF(TB_Entradas[Código Produto],F6,TB_Entradas[Quantidade Comprada]) -> 0 | J6: 4 | K6: abr | L6: =SUMIF(TB_Saídas[Mês],'Base Cálculos'!J6,#REF!) -> #REF! | M6: =SUMIF(TB_Entradas[Mês],'Base Cálculos'!J6,#REF!) -> #REF! | P6: =K6 -> abr | Q6: =SUMIFS(TB_Entradas[Quantidade Comprada],TB_Entradas[Código Produto],$O$3,TB_Entradas[Mês],J6) -> 0 | R6: =SUMIFS(TB_Saídas[Quantidade Vendida],#REF!,$O$3,TB_Saídas[Mês],'Base Cálculos'!J6) -> #REF!
A7: Quibe | B7: =SUMIF(#REF!,A7,TB_Saídas[Quantidade Vendida]) -> #REF! | C7: =SUMIF(#REF!,A7,#REF!) -> #REF! | E7: 5º | F7: =_xlfn.XLOOKUP(G7,B:B,A:A,"",0) -> #REF! | G7: =LARGE(B:B,5) -> #REF! | H7: =SUMIF(TB_Entradas[Código Produto],F7,TB_Entradas[Quantidade Comprada]) -> 0 | J7: 5 | K7: mai | L7: =SUMIF(TB_Saídas[Mês],'Base Cálculos'!J7,#REF!) -> #REF! | M7: =SUMIF(TB_Entradas[Mês],'Base Cálculos'!J7,#REF!) -> #REF! | P7: =K7 -> mai | Q7: =SUMIFS(TB_Entradas[Quantidade Comprada],TB_Entradas[Código Produto],$O$3,TB_Entradas[Mês],J7) -> 0 | R7: =SUMIFS(TB_Saídas[Quantidade Vendida],#REF!,$O$3,TB_Saídas[Mês],'Base Cálculos'!J7) -> #REF!
A8: Chá | B8: =SUMIF(#REF!,A8,TB_Saídas[Quantidade Vendida]) -> #REF! | C8: =SUMIF(#REF!,A8,#REF!) -> #REF! | J8: 6 | K8: jun | L8: =SUMIF(TB_Saídas[Mês],'Base Cálculos'!J8,#REF!) -> #REF! | M8: =SUMIF(TB_Entradas[Mês],'Base Cálculos'!J8,#REF!) -> #REF! | P8: =K8 -> jun | Q8: =SUMIFS(TB_Entradas[Quantidade Comprada],TB_Entradas[Código Produto],$O$3,TB_Entradas[Mês],J8) -> 0 | R8: =SUMIFS(TB_Saídas[Quantidade Vendida],#REF!,$O$3,TB_Saídas[Mês],'Base Cálculos'!J8) -> #REF!
A9: Manteiga | B9: =SUMIF(#REF!,A9,TB_Saídas[Quantidade Vendida]) -> #REF! | C9: =SUMIF(#REF!,A9,#REF!) -> #REF! | J9: 7 | K9: jul | L9: =SUMIF(TB_Saídas[Mês],'Base Cálculos'!J9,#REF!) -> #REF! | M9: =SUMIF(TB_Entradas[Mês],'Base Cálculos'!J9,#REF!) -> #REF! | P9: =K9 -> jul | Q9: =SUMIFS(TB_Entradas[Quantidade Comprada],TB_Entradas[Código Produto],$O$3,TB_Entradas[Mês],J9) -> 0 | R9: =SUMIFS(TB_Saídas[Quantidade Vendida],#REF!,$O$3,TB_Saídas[Mês],'Base Cálculos'!J9) -> #REF!
A10: Requeijão | B10: =SUMIF(#REF!,A10,TB_Saídas[Quantidade Vendida]) -> #REF! | C10: =SUMIF(#REF!,A10,#REF!) -> #REF! | E10: Top 5 Faturamento | J10: 8 | K10: ago | L10: =SUMIF(TB_Saídas[Mês],'Base Cálculos'!J10,#REF!) -> #REF! | M10: =SUMIF(TB_Entradas[Mês],'Base Cálculos'!J10,#REF!) -> #REF! | P10: =K10 -> ago | Q10: =SUMIFS(TB_Entradas[Quantidade Comprada],TB_Entradas[Código Produto],$O$3,TB_Entradas[Mês],J10) -> 0 | R10: =SUMIFS(TB_Saídas[Quantidade Vendida],#REF!,$O$3,TB_Saídas[Mês],'Base Cálculos'!J10) -> #REF!
A11: Chocolate Quente | B11: =SUMIF(#REF!,A11,TB_Saídas[Quantidade Vendida]) -> #REF! | C11: =SUMIF(#REF!,A11,#REF!) -> #REF! | F11: Produto | G11: Faturamento | J11: 9 | K11: set | L11: =SUMIF(TB_Saídas[Mês],'Base Cálculos'!J11,#REF!) -> #REF! | M11: =SUMIF(TB_Entradas[Mês],'Base Cálculos'!J11,#REF!) -> #REF! | P11: =K11 -> set | Q11: =SUMIFS(TB_Entradas[Quantidade Comprada],TB_Entradas[Código Produto],$O$3,TB_Entradas[Mês],J11) -> 0 | R11: =SUMIFS(TB_Saídas[Quantidade Vendida],#REF!,$O$3,TB_Saídas[Mês],'Base Cálculos'!J11) -> #REF!
A12: Leite | B12: =SUMIF(#REF!,A12,TB_Saídas[Quantidade Vendida]) -> #REF! | C12: =SUMIF(#REF!,A12,#REF!) -> #REF! | E12: 1º | F12: =_xlfn.XLOOKUP(G12,C:C,A:A,"",0) -> #REF! | G12: =LARGE(C:C,1) -> #REF! | J12: 10 | K12: out | L12: =SUMIF(TB_Saídas[Mês],'Base Cálculos'!J12,#REF!) -> #REF! | M12: =SUMIF(TB_Entradas[Mês],'Base Cálculos'!J12,#REF!) -> #REF! | P12: =K12 -> out | Q12: =SUMIFS(TB_Entradas[Quantidade Comprada],TB_Entradas[Código Produto],$O$3,TB_Entradas[Mês],J12) -> 0 | R12: =SUMIFS(TB_Saídas[Quantidade Vendida],#REF!,$O$3,TB_Saídas[Mês],'Base Cálculos'!J12) -> #REF!
A13: Açúcar | B13: =SUMIF(#REF!,A13,TB_Saídas[Quantidade Vendida]) -> #REF! | C13: =SUMIF(#REF!,A13,#REF!) -> #REF! | E13: 2º | F13: =_xlfn.XLOOKUP(G13,C:C,A:A,"",0) -> #REF! | G13: =LARGE(C:C,2) -> #REF! | J13: 11 | K13: nov | L13: =SUMIF(TB_Saídas[Mês],'Base Cálculos'!J13,#REF!) -> #REF! | M13: =SUMIF(TB_Entradas[Mês],'Base Cálculos'!J13,#REF!) -> #REF! | P13: =K13 -> nov | Q13: =SUMIFS(TB_Entradas[Quantidade Comprada],TB_Entradas[Código Produto],$O$3,TB_Entradas[Mês],J13) -> 0 | R13: =SUMIFS(TB_Saídas[Quantidade Vendida],#REF!,$O$3,TB_Saídas[Mês],'Base Cálculos'!J13) -> #REF!
A14: Mini Pizza | B14: =SUMIF(#REF!,A14,TB_Saídas[Quantidade Vendida]) -> #REF! | C14: =SUMIF(#REF!,A14,#REF!) -> #REF! | E14: 3º | F14: =_xlfn.XLOOKUP(G14,C:C,A:A,"",0) -> #REF! | G14: =LARGE(C:C,3) -> #REF! | J14: 12 | K14: dez | L14: =SUMIF(TB_Saídas[Mês],'Base Cálculos'!J14,#REF!) -> #REF! | M14: =SUMIF(TB_Entradas[Mês],'Base Cálculos'!J14,#REF!) -> #REF! | P14: =K14 -> dez | Q14: =SUMIFS(TB_Entradas[Quantidade Comprada],TB_Entradas[Código Produto],$O$3,TB_Entradas[Mês],J14) -> 0 | R14: =SUMIFS(TB_Saídas[Quantidade Vendida],#REF!,$O$3,TB_Saídas[Mês],'Base Cálculos'!J14) -> #REF!
A15: Chantilly | B15: =SUMIF(#REF!,A15,TB_Saídas[Quantidade Vendida]) -> #REF! | C15: =SUMIF(#REF!,A15,#REF!) -> #REF! | E15: 4º | F15: =_xlfn.XLOOKUP(G15,C:C,A:A,"",0) -> #REF! | G15: =LARGE(C:C,4) -> #REF!
A16: Pão de Queijo | B16: =SUMIF(#REF!,A16,TB_Saídas[Quantidade Vendida]) -> #REF! | C16: =SUMIF(#REF!,A16,#REF!) -> #REF! | E16: 5º | F16: =_xlfn.XLOOKUP(G16,C:C,A:A,"",0) -> #REF! | G16: =LARGE(C:C,5) -> #REF!
A17: Suco de Laranja | B17: =SUMIF(#REF!,A17,TB_Saídas[Quantidade Vendida]) -> #REF! | C17: =SUMIF(#REF!,A17,#REF!) -> #REF!
A18: Hamburguer | B18: =SUMIF(#REF!,A18,TB_Saídas[Quantidade Vendida]) -> #REF! | C18: =SUMIF(#REF!,A18,#REF!) -> #REF!
A19: Frango | B19: =SUMIF(#REF!,A19,TB_Saídas[Quantidade Vendida]) -> #REF! | C19: =SUMIF(#REF!,A19,#REF!) -> #REF!
A20: Água | B20: =SUMIF(#REF!,A20,TB_Saídas[Quantidade Vendida]) -> #REF! | C20: =SUMIF(#REF!,A20,#REF!) -> #REF!
A21: Cerveja | B21: =SUMIF(#REF!,A21,TB_Saídas[Quantidade Vendida]) -> #REF! | C21: =SUMIF(#REF!,A21,#REF!) -> #REF!
A22: Queijo | B22: =SUMIF(#REF!,A22,TB_Saídas[Quantidade Vendida]) -> #REF! | C22: =SUMIF(#REF!,A22,#REF!) -> #REF!
A23: Presunto | B23: =SUMIF(#REF!,A23,TB_Saídas[Quantidade Vendida]) -> #REF! | C23: =SUMIF(#REF!,A23,#REF!) -> #REF!
A24: Mortadela | B24: =SUMIF(#REF!,A24,TB_Saídas[Quantidade Vendida]) -> #REF! | C24: =SUMIF(#REF!,A24,#REF!) -> #REF!
A25: Peito de Peru | B25: =SUMIF(#REF!,A25,TB_Saídas[Quantidade Vendida]) -> #REF! | C25: =SUMIF(#REF!,A25,#REF!) -> #REF!
A26: Refrigerante | B26: =SUMIF(#REF!,A26,TB_Saídas[Quantidade Vendida]) -> #REF! | C26: =SUMIF(#REF!,A26,#REF!) -> #REF!
A27: Enroladinho | B27: =SUMIF(#REF!,A27,TB_Saídas[Quantidade Vendida]) -> #REF! | C27: =SUMIF(#REF!,A27,#REF!) -> #REF!

Sheet Gráficos Din
B3: Rótulos de Coluna
B4: jan | D4: fev | F4: mar | H4: abr | J4: mai | L4: jun | N4: jul | P4: ago | R4: set | T4: out | V4: nov | X4: dez
A6: Rótulos de Linha | B6: Custo | C6: Qtd | D6: Custo | E6: Qtd | F6: Custo | G6: Qtd | H6: Custo | I6: Qtd | J6: Custo | K6: Qtd | L6: Custo | M6: Qtd | N6: Custo | O6: Qtd | P6: Custo | Q6: Qtd | R6: Custo | S6: Qtd | T6: Custo | U6: Qtd | V6: Custo | W6: Qtd | X6: Custo | Y6: Qtd
A7: Água | V7: 25 | W7: 100
A8: Café | B8: 200 | C8: 100 | D8: 250 | E8: 125 | F8: 300 | G8: 150 | H8: 300 | I8: 150 | J8: 200 | K8: 100 | L8: 300 | M8: 150 | N8: 300 | O8: 150 | P8: 300 | Q8: 150 | R8: 360 | S8: 180 | T8: 200 | U8: 100 | V8: 160 | W8: 80 | X8: 400 | Y8: 200
A9: Cerveja | D9: 37.5 | E9: 50
A10: Chocolate Quente | B10: 22.5 | C10: 90 | D10: 20 | E10: 80 | F10: 10 | G10: 40 | H10: 15 | I10: 60 | J10: 11.25 | K10: 45 | L10: 28.75 | M10: 115 | N10: 30 | O10: 120 | P10: 8.75 | Q10: 35 | R10: 8.5 | S10: 34 | T10: 11.5 | U10: 46 | V10: 11.25 | W10: 45 | X10: 10 | Y10: 40
A11: Coxinha | B11: 50 | C11: 100 | D11: 50 | E11: 100 | F11: 25 | G11: 50 | H11: 25 | I11: 50 | J11: 25 | K11: 50 | L11: 22.5 | M11: 45 | N11: 10 | O11: 20 | P11: 15 | Q11: 30 | R11: 7.5 | S11: 15 | T11: 27.5 | U11: 55 | V11: 17.5 | W11: 35
A12: Frango | R12: 225 | S12: 50
A13: Hamburguer | J13: 480 | K13: 60
A14: Mini Pizza | P14: 100 | Q14: 100
A15: Pão de Queijo | B15: 25 | C15: 100 | D15: 21.25 | E15: 85 | F15: 12.5 | G15: 50 | H15: 22.5 | I15: 90 | J15: 7.5 | K15: 30 | L15: 25 | M15: 100 | N15: 15 | O15: 60 | P15: 7.5 | Q15: 30 | R15: 5 | S15: 20 | T15: 8.75 | U15: 35 | V15: 5 | W15: 20
A16: Refrigerante | F16: 500 | G16: 250 | R16: 200 | S16: 100
A17: Suco de Laranja | F17: 75 | G17: 100
A18: Total Geral | B18: 297.5 | C18: 390 | D18: 378.75 | E18: 440 | F18: 922.5 | G18: 640 | H18: 362.5 | I18: 350 | J18: 723.75 | K18: 285 | L18: 376.25 | M18: 410 | N18: 355 | O18: 350 | P18: 431.25 | Q18: 345 | R18: 806 | S18: 399 | T18: 247.75 | U18: 236 | V18: 218.75 | W18: 280 | X18: 410 | Y18: 240

Sheet Tab Din
A3: Soma de Quantidade Comprada | B3: Rótulos de Coluna
B4: jan | C4: fev | D4: mar | E4: abr | F4: mai | G4: jun | H4: jul | I4: ago | J4: set | K4: out | L4: nov | M4: dez | N4: Total Geral
A5: Rótulos de Linha
A6: Água | L6: 100 | N6: 100
A7: Café | B7: 100 | C7: 125 | D7: 150 | E7: 150 | F7: 100 | G7: 150 | H7: 150 | I7: 150 | J7: 180 | K7: 100 | L7: 80 | M7: 200 | N7: 1635
A8: Cerveja | C8: 50 | N8: 50
A9: Chocolate Quente | B9: 90 | C9: 80 | D9: 40 | E9: 60 | F9: 45 | G9: 115 | H9: 120 | I9: 35 | J9: 34 | K9: 46 | L9: 45 | M9: 40 | N9: 750
A10: Coxinha | B10: 100 | C10: 100 | D10: 50 | E10: 50 | F10: 50 | G10: 45 | H10: 20 | I10: 30 | J10: 15 | K10: 55 | L10: 35 | N10: 550
A11: Frango | J11: 50 | N11: 50
A12: Hamburguer | F12: 60 | N12: 60
A13: Mini Pizza | I13: 100 | N13: 100
A14: Pão de Queijo | B14: 100 | C14: 85 | D14: 50 | E14: 90 | F14: 30 | G14: 100 | H14: 60 | I14: 30 | J14: 20 | K14: 35 | L14: 20 | N14: 620
A15: Refrigerante | D15: 250 | J15: 100 | N15: 350
A16: Suco de Laranja | D16: 100 | N16: 100
A17: Total Geral | B17: 390 | C17: 440 | D17: 640 | E17: 350 | F17: 285 | G17: 410 | H17: 350 | I17: 345 | J17: 399 | K17: 236 | L17: 280 | M17: 240 | N17: 4365
A37: Rótulos de Linha | B37: Preço Unit | C37: Soma de Estoque Mínimo | I37: Mesma segmentação de dadoos para duas tabelas dinâmicas
A38: Açúcar | B38: 2 | C38: 4
A39: Água | B39: 2 | C39: 5
A40: Café | B40: 6 | C40: 50
A41: Cerveja | B41: 8 | C41: 5
A42: Chá | B42: 2 | C42: 15
A43: Chantilly | B43: 1.5 | C43: 2
A44: Chocolate Quente | B44: 8.5 | C44: 10
A45: Coxinha | B45: 6.5 | C45: 50
A46: Empada | B46: 4 | C46: 50
A47: Enroladinho | B47: 5 | C47: 10
A48: Esfiha | B48: 4.5 | C48: 50
A49: Frango | B49: 15 | C49: 2
... A65: Total Geral | B65: 142.5 | C65: 445
A71: Tab Din pelo Modelo de Dados
A72: Rótulos de Linha | B72: Qtd Comprada | C72: Soma de Custo Compra
A73: Distribuídora KS
A74: Água | B74: 100 | C74: 25
A75: Cerveja | B75: 50 | C75: 37.5
A76: Refrigerante | B76: 350 | C76: 700
A77: Frigorífico Z
A78: Frango | B78: 50 | C78: 225
A79: Hamburguer | B79: 60 | C79: 480
A80: Mercado Express
A81: Café | B81: 1635 | C81: 3270
...

Sheet Produtos
F1: Cadastro de Produtos
B4: Código Produto | C4: Produto | D4: Unidade de Medida | E4: Estoque Mínimo | F4: Custo Unitário | G4: Preço Unitário
B5: 1 | C5: Café | D5: Unidade | E5: 50 | F5: 2 | G5: 6
B6: 2 | C6: Pão | D6: Kg | E6: 5 | F6: 1.5 | G6: 3
B7: 3 | C7: Coxinha | D7: Kg | E7: 50 | F7: 0.5 | G7: 6.5
B8: 4 | C8: Esfiha | D8: Kg | E8: 50 | F8: 1 | G8: 4.5
B9: 5 | C9: Risoles | D9: Kg | E9: 50 | F9: 1 | G9: 4
B10: 6 | C10: Empada | D10: Kg | E10: 50 | F10: 1 | G10: 4
B11: 7 | C11: Quibe | D11: Kg | E11: 50 | F11: 0.5 | G11: 4
B12: 8 | C12: Chá | D12: Unidade | E12: 15 | F12: 0.5 | G12: 2
B13: 9 | C13: Manteiga | D13: Unidade | E13: 15 | F13: 0.25 | G13: 1
B14: 10 | C14: Requeijão | D14: Unidade | E14: 15 | F14: 0.25 | G14: 1
B15: 11 | C15: Chocolate Quente | D15: Caixa | E15: 10 | F15: 0.25 | G15: 8.5
B16: 12 | C16: Leite | D16: Caixa | E16: 12 | F16: 10 | G16: 5
... B31: 27 | C31: Enroladinho | D31: Kg | E31: 10 | F31: 0.25 | G31: 5

Sheet Fornecedor
F1: Cadastro de Fornecedor
B5: Código | C5: Empresa | D5: Telefone | E5: Responsável | F5: E-mail
B6: 1 | C6: Mercado Express | D6: (11) 1122-4422 | E6: Maria | F6: maria@mercadoexpress.com.br
B7: 2 | C7: Frigorífico Z | D7: (11) 1001-2022 | E7: Carlos | F7: carlos@frigoríficoz.com.br
B8: 3 | C8: Distribuídora KS | D8: (11) 1300-4033 | E8: Eduardo | F8: eduardo@distribuídoraks.com.br
B9: 4 | C9: Salgados Gran | D9: (11) 1400-3022 | E9: Claudia | F9: claudia@salgadosgran.com.br

Sheet Entradas
F1: Controle de Entradas
B5: Mês | C5: Data | D5: Código Produto | E5: Fornecedor | F5: Quantidade Comprada | H5: Despesas
B6: =MONTH(TB_Entradas[[#This Row],[Data]]) -> 1 | C6: 44566 | D6: 1 | E6: 1 | F6: 100 | H6: 5530
B7: =MONTH(TB_Entradas[[#This Row],[Data]]) -> 1 | C7: 44566 | D7: 3 | E7: 4 | F7: 100
B8: =MONTH(TB_Entradas[[#This Row],[Data]]) -> 1 | C8: 44576 | D8: 11 | E8: 1 | F8: 90
B9: =MONTH(TB_Entradas[[#This Row],[Data]]) -> 1 | C9: 44578 | D9: 16 | E9: 4 | F9: 100
B10: =MONTH(TB_Entradas[[#This Row],[Data]]) -> 2 | C10: 44593 | D10: 16 | E10: 4 | F10: 85
B11: =MONTH(TB_Entradas[[#This Row],[Data]]) -> 2 | C11: 44594 | D11: 11 | E11: 1 | F11: 80
B12: =MONTH(TB_Entradas[[#This Row],[Data]]) -> 2 | C12: 44598 | D12: 1 | E12: 1 | F12: 125
B13: =MONTH(TB_Entradas[[#This Row],[Data]]) -> 2 | C13: 44602 | D13: 21 | E13: 3 | F13: 50
B14: =MONTH(TB_Entradas[[#This Row],[Data]]) -> 2 | C14: 44612 | D14: 3 | E14: 4 | F14: 100
B15: =MONTH(TB_Entradas[[#This Row],[Data]]) -> 3 | C15: 44625 | D15: 26 | E15: 3 | F15: 250
B16: =MONTH(TB_Entradas[[#This Row],[Data]]) -> 3 | C16: 44630 | D16: 16 | E16: 4 | F16: 50
B17: =MONTH(TB_Entradas[[#This Row],[Data]]) -> 3 | C17: 44635 | D17: 1 | E17: 1 | F17: 150
B18: =MONTH(TB_Entradas[[#This Row],[Data]]) -> 3 | C18: 44637 | D18: 17 | E18: 1 | F18: 100
... B59: =MONTH(TB_Entradas[[#This Row],[Data]]) -> 12 | C59: 44910 | D59: 11 | E59: 1 | F59: 40

Sheet Saídas
E1: Controle de Saídas
B5: Mês | C5: Data | D5: Código Produto | E5: Quantidade Vendida | H5: Total Preco Venda | I5: Media Venda
B6: =MONTH(TB_Saídas[[#This Row],[Data]]) -> 1 | C6: 44566 | D6: 3 | E6: 30 | H6: 19042.5 | I6: 45.526316
B7: =MONTH(TB_Saídas[[#This Row],[Data]]) -> 1 | C7: 44567 | D7: 1 | E7: 80
B8: =MONTH(TB_Saídas[[#This Row],[Data]]) -> 1 | C8: 44581 | D8: 16 | E8: 50
B9: =MONTH(TB_Saídas[[#This Row],[Data]]) -> 1 | C9: 44586 | D9: 11 | E9: 50
B10: =MONTH(TB_Saídas[[#This Row],[Data]]) -> 2 | C10: 44597 | D10: 16 | E10: 30
B11: =MONTH(TB_Saídas[[#This Row],[Data]]) -> 2 | C11: 44598 | D11: 1 | E11: 110
B12: =MONTH(TB_Saídas[[#This Row],[Data]]) -> 2 | C12: 44602 | D12: 11 | E12: 75
B13: =MONTH(TB_Saídas[[#This Row],[Data]]) -> 2 | C13: 44620 | D13: 3 | E13: 20
B14: =MONTH(TB_Saídas[[#This Row],[Data]]) -> 3 | C14: 44626 | D14: 26 | E14: 110
B15: =MONTH(TB_Saídas[[#This Row],[Data]]) -> 3 | C15: 44631 | D15: 16 | E15: 40
B16: =MONTH(TB_Saídas[[#This Row],[Data]]) -> 3 | C16: 44646 | D16: 11 | E16: 50
B17: =MONTH(TB_Saídas[[#This Row],[Data]]) -> 3 | C17: 44649 | D17: 3 | E17: 15
B18: =MONTH(TB_Saídas[[#This Row],[Data]]) -> 3 | C18: 44630 | D18: 1 | E18: 100
... B62: =MONTH(TB_Saídas[[#This Row],[Data]]) -> 12 | C62: 44917 | D62: 11 | E62: 23

Sheet Consulta
G1: Consulta
D5: Data | F5: Produto
D6: <10/05/2022 | F6: ="=Café" -> =Café
D8: Quantidade Vendida | F8: =DSUM(TB_Saídas[#All],Consulta!D8,Consulta!D5:F6) -> 0
D10: Quantidade em Estoque | F10: =DSUM(TB_Entradas[#All],"Quantidade Comprada",Consulta!D5:F6)-F8 -> 0
D12: Valor da Compra | F12: =DSUM(TB_Entradas[#All],Consulta!D12,Consulta!D5:F6) -> #VALUE!
D14: Valor de Venda | F14: =DSUM(TB_Saídas[#All],Consulta!D14,Consulta!D5:F6) -> #VALUE!

Sheet Controle de Estoque
F1: Controle de Estoque
B5: Produto | C5: Entradas | D5: Saídas | E5: Saldo em Estoque | F5: Estoque Mínimo | G5: Status do Estoque | H5: Valor de Venda | I5: Custo Total | J5: Lucro
B6: Refrigerante | C6: =IFERROR(SUMIF(TB_Entradas[Código Produto],TB_ControleEstoque[[#This Row],[Produto]],TB_Entradas[Quantidade Comprada]),0) -> 0 | D6: =IFERROR(SUMIF(#REF!,TB_ControleEstoque[[#This Row],[Produto]],TB_Saídas[Quantidade Vendida]),0) -> 0 | E6: =TB_ControleEstoque[[#This Row],[Entradas]]-TB_ControleEstoque[[#This Row],[Saídas ]] -> 0 | F6: =_xlfn.XLOOKUP(TB_ControleEstoque[[#This Row],[Produto]],TB_Produtos[Produto],TB_Produtos[Estoque Mínimo],"Erro",0,1) -> 10 | G6: {=_xlfn.IFS(TB_ControleEstoque[[#This Row],[Saldo em Estoque]]>TB_ControleEstoque[[#This Row],[Estoque Mínimo]],"Estoque OK",TB_ControleEstoque[[#This Row],[Saldo em Estoque]]=0,"Estoque Zerado",1,"Repor Estoque")} -> Estoque Zerado | H6: =SUMIFS(#REF!,#REF!,TB_ControleEstoque[[#This Row],[Produto]]) -> #REF! | I6: =SUMIFS(#REF!,TB_Entradas[Código Produto],TB_ControleEstoque[[#This Row],[Produto]]) -> #REF! | J6: =TB_ControleEstoque[[#This Row],[Valor de Venda]]-TB_ControleEstoque[[#This Row],[Custo Total]] -> #REF!
B7: Café | C7: =IFERROR(SUMIF(TB_Entradas[Código Produto],TB_ControleEstoque[[#This Row],[Produto]],TB_Entradas[Quantidade Comprada]),0) -> 0 | D7: =IFERROR(SUMIF(#REF!,TB_ControleEstoque[[#This Row],[Produto]],TB_Saídas[Quantidade Vendida]),0) -> 0 | E7: =TB_ControleEstoque[[#This Row],[Entradas]]-TB_ControleEstoque[[#This Row],[Saídas ]] -> 0 | F7: =_xlfn.XLOOKUP(TB_ControleEstoque[[#This Row],[Produto]],TB_Produtos[Produto],TB_Produtos[Estoque Mínimo],"Erro",0,1) -> 50 | G7: {=_xlfn.IFS(TB_ControleEstoque[[#This Row],[Saldo em Estoque]]>TB_ControleEstoque[[#This Row],[Estoque Mínimo]],"Estoque OK",TB_ControleEstoque[[#This Row],[Saldo em Estoque]]=0,"Estoque Zerado",1,"Repor Estoque")} -> Estoque Zerado | H7: =SUMIFS(#REF!,#REF!,TB_ControleEstoque[[#This Row],[Produto]]) -> #REF! | I7: =SUMIFS(#REF!,TB_Entradas[Código Produto],TB_ControleEstoque[[#This Row],[Produto]]) -> #REF! | J7: =TB_ControleEstoque[[#This Row],[Valor de Venda]]-TB_ControleEstoque[[#This Row],[Custo Total]] -> #REF! | N7: Produto Mais Rentável
B8: Suco de Laranja | C8: =IFERROR(SUMIF(TB_Entradas[Código Produto],TB_ControleEstoque[[#This Row],[Produto]],TB_Entradas[Quantidade Comprada]),0) -> 0 | D8: =IFERROR(SUMIF(#REF!,TB_ControleEstoque[[#This Row],[Produto]],TB_Saídas[Quantidade Vendida]),0) -> 0 | E8: =TB_ControleEstoque[[#This Row],[Entradas]]-TB_ControleEstoque[[#This Row],[Saídas ]] -> 0 | F8: =_xlfn.XLOOKUP(TB_ControleEstoque[[#This Row],[Produto]],TB_Produtos[Produto],TB_Produtos[Estoque Mínimo],"Erro",0,1) -> 5 | G8: {=_xlfn.IFS(TB_ControleEstoque[[#This Row],[Saldo em Estoque]]>TB_ControleEstoque[[#This Row],[Estoque Mínimo]],"Estoque OK",TB_ControleEstoque[[#This Row],[Saldo em Estoque]]=0,"Estoque Zerado",1,"Repor Estoque")} -> Estoque Zerado | H8: =SUMIFS(#REF!,#REF!,TB_ControleEstoque[[#This Row],[Produto]]) -> #REF! | I8: =SUMIFS(#REF!,TB_Entradas[Código Produto],TB_ControleEstoque[[#This Row],[Produto]]) -> #REF! | J8: =TB_ControleEstoque[[#This Row],[Valor de Venda]]-TB_ControleEstoque[[#This Row],[Custo Total]] -> #REF! | N8: Lucro | P8: Produto
B9: Cerveja | C9: =IFERROR(SUMIF(TB_Entradas[Código Produto],TB_ControleEstoque[[#This Row],[Produto]],TB_Entradas[Quantidade Comprada]),0) -> 0 | D9: =IFERROR(SUMIF(#REF!,TB_ControleEstoque[[#This Row],[Produto]],TB_Saídas[Quantidade Vendida]),0) -> 0 | E9: =TB_ControleEstoque[[#This Row],[Entradas]]-TB_ControleEstoque[[#This Row],[Saídas ]] -> 0 | F9: =_xlfn.XLOOKUP(TB_ControleEstoque[[#This Row],[Produto]],TB_Produtos[Produto],TB_Produtos[Estoque Mínimo],"Erro",0,1) -> 5 | G9: {=_xlfn.IFS(TB_ControleEstoque[[#This Row],[Saldo em Estoque]]>TB_ControleEstoque[[#This Row],[Estoque Mínimo]],"Estoque OK",TB_ControleEstoque[[#This Row],[Saldo em Estoque]]=0,"Estoque Zerado",1,"Repor Estoque")} -> Estoque Zerado | H9: =SUMIFS(#REF!,#REF!,TB_ControleEstoque[[#This Row],[Produto]]) -> #REF! | I9: =SUMIFS(#REF!,TB_Entradas[Código Produto],TB_ControleEstoque[[#This Row],[Produto]]) -> #REF! | J9: =TB_ControleEstoque[[#This Row],[Valor de Venda]]-TB_ControleEstoque[[#This Row],[Custo Total]] -> #REF! | N9: =LARGE(TB_ControleEstoque[Lucro],1) -> #REF! | P9: =DGET(TB_ControleEstoque[#All],1,N8:N9) -> #NUM!
B10: Chocolate Quente | C10: =IFERROR(SUMIF(TB_Entradas[Código Produto],TB_ControleEstoque[[#This Row],[Produto]],TB_Entradas[Quantidade Comprada]),0) -> 0 | D10: =IFERROR(SUMIF(#REF!,TB_ControleEstoque[[#This Row],[Produto]],TB_Saídas[Quantidade Vendida]),0) -> 0 | E10: =TB_ControleEstoque[[#This Row],[Entradas]]-TB_ControleEstoque[[#This Row],[Saídas ]] -> 0 | F10: =_xlfn.XLOOKUP(TB_ControleEstoque[[#This Row],[Produto]],TB_Produtos[Produto],TB_Produtos[Estoque Mínimo],"Erro",0,1) -> 10 | G10: {=_xlfn.IFS(TB_ControleEstoque[[#This Row],[Saldo em Estoque]]>TB_ControleEstoque[[#This Row],[Estoque Mínimo]],"Estoque OK",TB_ControleEstoque[[#This Row],[Saldo em Estoque]]=0,"Estoque Zerado",1,"Repor Estoque")} -> Estoque Zerado | H10: =SUMIFS(#REF!,#REF!,TB_ControleEstoque[[#This Row],[Produto]]) -> #REF! | I10: =SUMIFS(#REF!,TB_Entradas[Código Produto],TB_ControleEstoque[[#This Row],[Produto]]) -> #REF! | J10: =TB_ControleEstoque[[#This Row],[Valor de Venda]]-TB_ControleEstoque[[#This Row],[Custo Total]] -> #REF!
B11: Pão de Queijo | C11: =IFERROR(SUMIF(TB_Entradas[Código Produto],TB_ControleEstoque[[#This Row],[Produto]],TB_Entradas[Quantidade Comprada]),0) -> 0 | D11: =IFERROR(SUMIF(#REF!,TB_ControleEstoque[[#This Row],[Produto]],TB_Saídas[Quantidade Vendida]),0) -> 0 | E11: =TB_ControleEstoque[[#This Row],[Entradas]]-TB_ControleEstoque[[#This Row],[Saídas ]] -> 0 | F11: =_xlfn.XLOOKUP(TB_ControleEstoque[[#This Row],[Produto]],TB_Produtos[Produto],TB_Produtos[Estoque Mínimo],"Erro",0,1) -> 10 | G11: {=_xlfn.IFS(TB_ControleEstoque[[#This Row],[Saldo em Estoque]]>TB_ControleEstoque[[#This Row],[Estoque Mínimo]],"Estoque OK",TB_ControleEstoque[[#This Row],[Saldo em Estoque]]=0,"Estoque Zerado",1,"Repor Estoque")} -> Estoque Zerado | H11: =SUMIFS(#REF!,#REF!,TB_ControleEstoque[[#This Row],[Produto]]) -> #REF! | I11: =SUMIFS(#REF!,TB_Entradas[Código Produto],TB_ControleEstoque[[#This Row],[Produto]]) -> #REF! | J11: =TB_ControleEstoque[[#This Row],[Valor de Venda]]-TB_ControleEstoque[[#This Row],[Custo Total]] -> #REF!
B12: Coxinha | C12: =IFERROR(SUMIF(TB_Entradas[Código Produto],TB_ControleEstoque[[#This Row],[Produto]],TB_Entradas[Quantidade Comprada]),0) -> 0 | D12: =IFERROR(SUMIF(#REF!,TB_ControleEstoque[[#This Row],[Produto]],TB_Saídas[Quantidade Vendida]),0) -> 0 | E12: =TB_ControleEstoque[[#This Row],[Entradas]]-TB_ControleEstoque[[#This Row],[Saídas ]] -> 0 | F12: =_xlfn.XLOOKUP(TB_ControleEstoque[[#This Row],[Produto]],TB_Produtos[Produto],TB_Produtos[Estoque Mínimo],"Erro",0,1) -> 50 | G12: {=_xlfn.IFS(TB_ControleEstoque[[#This Row],[Saldo em Estoque]]>TB_ControleEstoque[[#This Row],[Estoque Mínimo]],"Estoque OK",TB_ControleEstoque[[#This Row],[Saldo em Estoque]]=0,"Estoque Zerado",1,"Repor Estoque")} -> Estoque Zerado | H12: =SUMIFS(#REF!,#REF!,TB_ControleEstoque[[#This Row],[Produto]]) -> #REF! | I12: =SUMIFS(#REF!,TB_Entradas[Código Produto],TB_ControleEstoque[[#This Row],[Produto]]) -> #REF! | J12: =TB_ControleEstoque[[#This Row],[Valor de Venda]]-TB_ControleEstoque[[#This Row],[Custo Total]] -> #REF!
B13: Frango | C13: =IFERROR(SUMIF(TB_Entradas[Código Produto],TB_ControleEstoque[[#This Row],[Produto]],TB_Entradas[Quantidade Comprada]),0) -> 0 | D13: =IFERROR(SUMIF(#REF!,TB_ControleEstoque[[#This Row],[Produto]],TB_Saídas[Quantidade Vendida]),0) -> 0 | E13: =TB_ControleEstoque[[#This Row],[Entradas]]-TB_ControleEstoque[[#This Row],[Saídas ]] -> 0 | F13: =_xlfn.XLOOKUP(TB_ControleEstoque[[#This Row],[Produto]],TB_Produtos[Produto],TB_Produtos[Estoque Mínimo],"Erro",0,1) -> 2 | G13: {=_xlfn.IFS(TB_ControleEstoque[[#This Row],[Saldo em Estoque]]>TB_ControleEstoque[[#This Row],[Estoque Mínimo]],"Estoque OK",TB_ControleEstoque[[#This Row],[Saldo em Estoque]]=0,"Estoque Zerado",1,"Repor Estoque")} -> Estoque Zerado | H13: =SUMIFS(#REF!,#REF!,TB_ControleEstoque[[#This Row],[Produto]]) -> #REF! | I13: =SUMIFS(#REF!,TB_Entradas[Código Produto],TB_ControleEstoque[[#This Row],[Produto]]) -> #REF! | J13: =TB_ControleEstoque[[#This Row],[Valor de Venda]]-TB_ControleEstoque[[#This Row],[Custo Total]] -> #REF!
B14: Mini Pizza | C14: =IFERROR(SUMIF(TB_Entradas[Código Produto],TB_ControleEstoque[[#This Row],[Produto]],TB_Entradas[Quantidade Comprada]),0) -> 0 | D14: =IFERROR(SUMIF(#REF!,TB_ControleEstoque[[#This Row],[Produto]],TB_Saídas[Quantidade Vendida]),0) -> 0 | E14: =TB_ControleEstoque[[#This Row],[Entradas]]-TB_ControleEstoque[[#This Row],[Saídas ]] -> 0 | F14: =_xlfn.XLOOKUP(TB_ControleEstoque[[#This Row],[Produto]],TB_Produtos[Produto],TB_Produtos[Estoque Mínimo],"Erro",0,1) -> 10 | G14: {=_xlfn.IFS(TB_ControleEstoque[[#This Row],[Saldo em Estoque]]>TB_ControleEstoque[[#This Row],[Estoque Mínimo]],"Estoque OK",TB_ControleEstoque[[#This Row],[Saldo em Estoque]]=0,"Estoque Zerado",1,"Repor Estoque")} -> Estoque Zerado | H14: =SUMIFS(#REF!,#REF!,TB_ControleEstoque[[#This Row],[Produto]]) -> #REF! | I14: =SUMIFS(#REF!,TB_Entradas[Código Produto],TB_ControleEstoque[[#This Row],[Produto]]) -> #REF! | J14: =TB_ControleEstoque[[#This Row],[Valor de Venda]]-TB_ControleEstoque[[#This Row],[Custo Total]] -> #REF!
B15: Hamburguer | C15: =IFERROR(SUMIF(TB_Entradas[Código Produto],TB_ControleEstoque[[#This Row],[Produto]],TB_Entradas[Quantidade Comprada]),0) -> 0 | D15: =IFERROR(SUMIF(#REF!,TB_ControleEstoque[[#This Row],[Produto]],TB_Saídas[Quantidade Vendida]),0) -> 0 | E15: =TB_ControleEstoque[[#This Row],[Entradas]]-TB_ControleEstoque[[#This Row],[Saídas ]] -> 0 | F15: =_xlfn.XLOOKUP(TB_ControleEstoque[[#This Row],[Produto]],TB_Produtos[Produto],TB_Produtos[Estoque Mínimo],"Erro",0,1) -> 2 | G15: {=_xlfn.IFS(TB_ControleEstoque[[#This Row],[Saldo em Estoque]]>TB_ControleEstoque[[#This Row],[Estoque Mínimo]],"Estoque OK",TB_ControleEstoque[[#This Row],[Saldo em Estoque]]=0,"Estoque Zerado",1,"Repor Estoque")} -> Estoque Zerado | H15: =SUMIFS(#REF!,#REF!,TB_ControleEstoque[[#This Row],[Produto]]) -> #REF! | I15: =SUMIFS(#REF!,TB_Entradas[Código Produto],TB_ControleEstoque[[#This Row],[Produto]]) -> #REF! | J15: =TB_ControleEstoque[[#This Row],[Valor de Venda]]-TB_ControleEstoque[[#This Row],[Custo Total]] -> #REF!

Sheet Quadro de Resumo
AD1: Quadro de Resumo
C5: Dados 2022 | AB5: Consulta por Produto
AM7: Produto
D8: Produtos Vendidos: | N8: =COUNTA(_xlfn.UNIQUE(#REF!)) -> 1 | AC8: Dados: | AM8: Café
D11: Qtd em Estoque: | N11: =SUM(TB_ControleEstoque[Saldo em Estoque]) -> 0 | AC11: Qtd em Estoque: | AM11: =DSUM(TB_ControleEstoque[#All],TB_ControleEstoque[[#Headers],[Saldo em Estoque]],CriteriosConsultaProduto) -> 0
D14: Faturamento: | N14: =SUM(#REF!) -> #REF! | AC14: Faturamento: | AM14: =DSUM(TB_Saídas[#All],#REF!,CriteriosConsultaProduto) -> #REF!
D17: Despesas: | N17: =SUM(#REF!) -> #REF! | AC17: Despesas: | AM17: =DSUM(TB_Entradas[#All],#REF!,CriteriosConsultaProduto) -> #REF!
D20: Lucro: | N20: =N14-N17 -> #REF! | AC20: Lucro: | AM20: =AM14-AM17 -> #REF!
D23: % Lucro: | N23: =N20/N17 -> #REF! | AC23: % Lucro: | AM23: =AM20/AM17 -> #REF!
